<robot name="mower">

  <link name="base_link">
    <visual>
      <geometry>
        <box size="0.6 0.4 0.2"/>
      </geometry>
    </visual>
    <collision>
      <geometry>
        <box size="0.6 0.4 0.2"/>
      </geometry>
    </collision>
    <inertial>
    <origin xyz="0 0 0.1" rpy="0 0 0"/> <mass value="5.0"/>
    <inertia ixx="0.054" ixy="0.0" ixz="0.0" 
             iyy="0.120" iyz="0.0" 
             izz="0.141"/>
    </inertial>
  </link>

  <link name="left_wheel">
    <visual>
      <geometry>
        <cylinder radius="0.1" length="0.05"/>
      </geometry>
    </visual>
    <collision>
      <geometry>
        <cylinder radius="0.1" length="0.05"/>
      </geometry>
    </collision>
    <inertial>
    <origin xyz="0 0 0" rpy="1.5707 0 0"/> <mass value="0.5"/>
    <inertia ixx="0.00135" ixy="0.0" ixz="0.0" 
             iyy="0.00135" iyz="0.0" 
             izz="0.0025"/>
    </inertial>    
  </link>

  <link name="right_wheel">
    <visual>
      <geometry>
        <cylinder radius="0.1" length="0.05"/>
      </geometry>
    </visual>
    <collision>
      <geometry>
        <cylinder radius="0.1" length="0.05"/>
      </geometry>
    </collision>
    <inertial>
    <origin xyz="0 0 0" rpy="1.5707 0 0"/> <mass value="0.5"/>
    <inertia ixx="0.00135" ixy="0.0" ixz="0.0" 
             iyy="0.00135" iyz="0.0" 
             izz="0.0025"/>
    </inertial>
  </link>

  <!-- Differential drive -->
  <joint name="left_wheel_joint" type="continuous">
    <parent link="base_link"/>
    <child link="left_wheel"/>
    <origin xyz="0 0.2 0"/>
    <axis xyz="0 1 0"/>
  </joint>

  <joint name="right_wheel_joint" type="continuous">
    <parent link="base_link"/>
    <child link="right_wheel"/>
    <origin xyz="0 -0.2 0"/>
    <axis xyz="0 1 0"/>
  </joint>
  
<gazebo>
  <plugin name="diff_drive" filename="libgazebo_ros_diff_drive.so">

    <ros>
      <remapping>cmd_vel:=cmd_vel</remapping>
      <remapping>odom:=odom</remapping>
    </ros>

    <update_rate>50</update_rate>

    <left_joint>left_wheel_joint</left_joint>
    <right_joint>right_wheel_joint</right_joint>

    <wheel_separation>0.4</wheel_separation>
    <wheel_diameter>0.2</wheel_diameter>

    <max_wheel_torque>20</max_wheel_torque>
    <max_wheel_acceleration>1.0</max_wheel_acceleration>

    <publish_odom>true</publish_odom>
    <publish_odom_tf>true</publish_odom_tf>
    <publish_wheel_tf>true</publish_wheel_tf>

    <odometry_frame>odom</odometry_frame>
    <robot_base_frame>base_link</robot_base_frame>
  </plugin>
</gazebo>

</robot>
